2009-03-18 00:00:00 2009-03-18
2009-03-18 21:06:44
21:06:44
Traceback (most recent call last):
  File "py-script.py", line 28, in <module>
    execfile(sys.argv[0])
  File "dates.py", line 13, in <module>
    print datetime(*time_value)
ValueError: year is out of range
